<?xml version="1.0"?>
<robot name="nexus_4wd_mecanum" xmlns:xacro="http://ros.org/wiki/xacro">

  <xacro:property name="PI" value="3.1415926535897931" />

  <xacro:property name="wheel_radius" value="0.050" />
  <xacro:property name="wheel_width" value="0.0505" />

  <material name="yellow"><color rgba="0.8 0.8 0.0 1.0" /></material>
  <material name="black"><color rgba="0.15 0.15 0.15 1.0" /></material>
  <material name="dark_grey"><color rgba="0.2 0.2 0.2 1.0" /></material>
  <material name="light_grey"><color rgba="0.4 0.4 0.4 1.0" /></material>

  <link name="base_footprint"></link>

  <joint name="base_link_joint" type="fixed">
    <origin xyz="0 0 0.05" rpy="0 0 0" />
    <parent link="base_footprint"/>
    <child link="base_link" />
  </joint>

  <link name="base_link">
    <visual>
      <origin xyz="0 0 0" rpy="0 0 0" />
      <geometry>
        <mesh filename="package://cpr_inspection_gazebo/meshes/nexus_base_link.STL" scale="0.001 0.001 0.001"/>
      </geometry>
      <material name="yellow" />
    </visual>
    <collision>
      <origin xyz="0 0 0"/>
      <geometry>
        <mesh filename="package://cpr_inspection_gazebo/meshes/nexus_base_link_collision.STL" scale="0.001 0.001 0.001"/>
      </geometry>
    </collision>
    <inertial>
      <!-- Inertia from CAD model, filled box assumption -->
      <origin xyz="-0.01103 0 0.002" rpy="0 0 0"/>
      <mass value="2.844"/>
      <inertia
        ixx="0.018819942" ixy="0" ixz="-0.000101519"
        iyy="0.057333716" iyz="0"
        izz="0.074201740"/>
    </inertial>
  </link>

  <joint name="upper_left_wheel_shaft_joint" type="fixed">
    <origin xyz="0.150 0.108 0.0" rpy="0 0 0" />
    <parent link="base_link"/>
    <child link="upper_left_wheel_shaft" />
  </joint>

  <link name="upper_left_wheel_shaft">
    <visual>
      <origin xyz="0 0 0" rpy="0 0 0" />
      <geometry>
        <mesh filename="package://cpr_inspection_gazebo/meshes/wheel_shaft.STL" scale="0.001 0.001 0.001"/>
      </geometry>
      <material name="black" />
    </visual>
    <collision>
      <origin xyz="0 0 0"/>
      <geometry>
        <mesh filename="package://cpr_inspection_gazebo/meshes/wheel_shaft.STL" scale="0.001 0.001 0.001"/>
      </geometry>
    </collision>
    <inertial>
      <origin xyz="0 0.01221 0" rpy="0 0 0"/>
      <mass value="0.055"/>
      <inertia
        ixx="0.000021370" ixy="0" ixz="0"
        iyy="0.000009966" iyz="0"
        izz="0.000021370"/>
    </inertial>
  </link>

  <joint name="lower_left_wheel_shaft_joint" type="fixed">
    <origin xyz="-0.150 0.108 0.0" rpy="0 0 0" />
    <parent link="base_link"/>
    <child link="lower_left_wheel_shaft" />
  </joint>

  <link name="lower_left_wheel_shaft">
    <visual>
      <origin xyz="0 0 0" rpy="0 0 0" />
      <geometry>
        <mesh filename="package://cpr_inspection_gazebo/meshes/wheel_shaft.STL" scale="0.001 0.001 0.001"/>
      </geometry>
      <material name="black" />
    </visual>
    <collision>
      <origin xyz="0 0 0"/>
      <geometry>
        <mesh filename="package://cpr_inspection_gazebo/meshes/wheel_shaft.STL" scale="0.001 0.001 0.001"/>
      </geometry>
    </collision>
    <inertial>
      <origin xyz="0 0.01221 0" rpy="0 0 0"/>
      <mass value="0.055"/>
      <inertia
        ixx="0.000021370" ixy="0" ixz="0"
        iyy="0.000009966" iyz="0"
        izz="0.000021370"/>
    </inertial>
  </link>

  <joint name="upper_right_wheel_shaft_joint" type="fixed">
    <origin xyz="0.150 -0.108 0.0" rpy="${PI} 0 0" />
    <parent link="base_link"/>
    <child link="upper_right_wheel_shaft" />
  </joint>

  <link name="upper_right_wheel_shaft">
    <visual>
      <origin xyz="0 0 0" rpy="0 0 0" />
      <geometry>
        <mesh filename="package://cpr_inspection_gazebo/meshes/wheel_shaft.STL" scale="0.001 0.001 0.001"/>
      </geometry>
      <material name="black" />
    </visual>
    <collision>
      <origin xyz="0 0 0"/>
      <geometry>
        <mesh filename="package://cpr_inspection_gazebo/meshes/wheel_shaft.STL" scale="0.001 0.001 0.001"/>
      </geometry>
    </collision>
    <inertial>
      <origin xyz="0 0.01221 0" rpy="0 0 0"/>
      <mass value="0.055"/>
      <inertia
        ixx="0.000021370" ixy="0" ixz="0"
        iyy="0.000009966" iyz="0"
        izz="0.000021370"/>
    </inertial>
  </link>

  <joint name="lower_right_wheel_shaft_joint" type="fixed">
    <origin xyz="-0.150 -0.108 0.0" rpy="${PI} 0 0" />
    <parent link="base_link"/>
    <child link="lower_right_wheel_shaft" />
  </joint>

  <link name="lower_right_wheel_shaft">
    <visual>
      <origin xyz="0 0 0" rpy="0 0 0" />
      <geometry>
        <mesh filename="package://cpr_inspection_gazebo/meshes/wheel_shaft.STL" scale="0.001 0.001 0.001"/>
      </geometry>
      <material name="black" />
    </visual>
    <collision>
      <origin xyz="0 0 0"/>
      <geometry>
        <mesh filename="package://cpr_inspection_gazebo/meshes/wheel_shaft.STL" scale="0.001 0.001 0.001"/>
      </geometry>
    </collision>
    <inertial>
      <origin xyz="0 0.01221 0" rpy="0 0 0"/>
      <mass value="0.055"/>
      <inertia
        ixx="0.000021370" ixy="0" ixz="0"
        iyy="0.000009966" iyz="0"
        izz="0.000021370"/>
    </inertial>
  </link>

  <joint name="upper_left_wheel_joint" type="continuous">
    <origin xyz="0 0.042 0" rpy="0 0 0" />
    <parent link="upper_left_wheel_shaft"/>
    <child link="upper_left_wheel" />
    <axis xyz="0 1 0"/>
  </joint>
  
  <link name="upper_left_wheel">
    <visual>
      <origin xyz="0 0 0" rpy="0 0 0" />
      <geometry>
        <mesh filename="package://cpr_inspection_gazebo/meshes/mecanum_wheel_left.STL" scale="0.001 0.001 0.001"/>
      </geometry>
      <material name="light_grey" />
    </visual>
    <collision>
      <origin xyz="0 0 0" rpy="${PI/2} 0 0"/>
      <geometry>
        <cylinder radius="${wheel_radius}" length="${wheel_width}"/>
      </geometry>
    </collision>
    <inertial>
      <origin xyz="0.0 0.0 0.0" rpy="0 0 0"/>
      <mass value="0.3844"/>
      <!-- Inertia based on cylinder -->
      <inertia
        ixx="0.000324824" ixy="0" ixz="0"
        iyy="0.000480000" iyz="0"
        izz="0.000324824"/>
    </inertial>
  </link>

  <joint name="lower_left_wheel_joint" type="continuous">
    <origin xyz="0 0.042 0" rpy="0 0 0" />
    <parent link="lower_left_wheel_shaft"/>
    <child link="lower_left_wheel" />
    <axis xyz="0 1 0"/>
  </joint>

  <link name="lower_left_wheel">
    <visual>
      <origin xyz="0 0 0" rpy="0 0 0" />
      <geometry>
        <mesh filename="package://cpr_inspection_gazebo/meshes/mecanum_wheel_right.STL" scale="0.001 0.001 0.001"/>
      </geometry>
      <material name="light_grey" />
    </visual>
    <collision>
      <origin xyz="0 0 0" rpy="${PI/2} 0 0"/>
      <geometry>
        <cylinder radius="${wheel_radius}" length="${wheel_width}"/>
      </geometry>
    </collision>
    <inertial>
      <origin xyz="0.0 0.0 0.0" rpy="0 0 0"/>
      <mass value="0.3844"/>
      <!-- Inertia based on cylinder -->
      <inertia
        ixx="0.000324824" ixy="0" ixz="0"
        iyy="0.000480000" iyz="0"
        izz="0.000324824"/>
    </inertial>
  </link>

  <joint name="upper_right_wheel_joint" type="continuous">
    <origin xyz="0 0.042 0" rpy="0 0 0" />
    <parent link="upper_right_wheel_shaft"/>
    <child link="upper_right_wheel" />
    <axis xyz="0 1 0"/>
  </joint>

  <link name="upper_right_wheel">
    <visual>
      <origin xyz="0 0 0" rpy="0 0 0" />
      <geometry>
        <mesh filename="package://cpr_inspection_gazebo/meshes/mecanum_wheel_right.STL" scale="0.001 0.001 0.001"/>
      </geometry>
      <material name="light_grey" />
    </visual>
    <collision>
      <origin xyz="0 0 0" rpy="${PI/2} 0 0"/>
      <geometry>
        <cylinder radius="${wheel_radius}" length="${wheel_width}"/>
      </geometry>
    </collision>
    <inertial>
      <origin xyz="0.0 0.0 0.0" rpy="0 0 0"/>
      <mass value="0.3844"/>
      <!-- Inertia based on cylinder -->
      <inertia
        ixx="0.000324824" ixy="0" ixz="0"
        iyy="0.000480000" iyz="0"
        izz="0.000324824"/>
    </inertial>
  </link>
  
  <joint name="lower_right_wheel_joint" type="continuous">
    <origin xyz="0 0.042 0" rpy="0 0 0" />
    <parent link="lower_right_wheel_shaft"/>
    <child link="lower_right_wheel" />
    <axis xyz="0 1 0"/>
  </joint>

  <link name="lower_right_wheel">
    <visual>
      <origin xyz="0 0 0" rpy="0 0 0" />
      <geometry>
        <mesh filename="package://cpr_inspection_gazebo/meshes/mecanum_wheel_left.STL" scale="0.001 0.001 0.001"/>
      </geometry>
      <material name="light_grey" />
    </visual>
    <collision>
      <origin xyz="0 0 0" rpy="${PI/2} 0 0"/>
      <geometry>
        <cylinder radius="${wheel_radius}" length="${wheel_width}"/>
      </geometry>
    </collision>
    <inertial>
      <origin xyz="0.0 0.0 0.0" rpy="0 0 0"/>
      <mass value="0.3844"/>
      <!-- Inertia based on cylinder -->
      <inertia
        ixx="0.000324824" ixy="0" ixz="0"
        iyy="0.000480000" iyz="0"
        izz="0.000324824"/>
    </inertial>
  </link>

  <joint name="left_sensor_joint" type="fixed">
    <origin xyz="0 0.108 0.010" rpy="0 0 ${PI/2}" />
    <parent link="base_link"/>
    <child link="left_sensor" />
  </joint>

  <link name="left_sensor">
    <visual>
      <origin xyz="0 0 0" rpy="${PI/2} 0 0" />
      <geometry>
        <mesh filename="package://cpr_inspection_gazebo/meshes/urm04.STL" scale="0.001 0.001 0.001"/>
      </geometry>
      <material name="black" />
    </visual>
  </link>

  <joint name="front_sensor_joint" type="fixed">
    <origin xyz="0.205 0 0.010" rpy="0 0 0" />
    <parent link="base_link"/>
    <child link="front_sensor" />
  </joint>

  <link name="front_sensor">
    <visual>
      <origin xyz="0 0 0" rpy="${PI/2} 0 0" />
      <geometry>
        <mesh filename="package://cpr_inspection_gazebo/meshes/urm04.STL" scale="0.001 0.001 0.001"/>
      </geometry>
      <material name="black" />
    </visual>
  </link>

  <joint name="right_sensor_joint" type="fixed">
    <origin xyz="0 -0.108 0.010" rpy="0 0 ${-PI/2}" />
    <parent link="base_link"/>
    <child link="right_sensor" />
  </joint>

  <link name="right_sensor">
    <visual>
      <origin xyz="0 0 0" rpy="${PI/2} 0 0" />
      <geometry>
        <mesh filename="package://cpr_inspection_gazebo/meshes/urm04.STL" scale="0.001 0.001 0.001"/>
      </geometry>
      <material name="black" />
    </visual>
  </link>

  <joint name="rear_sensor_joint" type="fixed">
    <origin xyz="-0.201 0 0.010" rpy="0 0 ${PI}" />
    <parent link="base_link"/>
    <child link="rear_sensor" />
  </joint>

  <link name="rear_sensor">
    <visual>
      <origin xyz="0 0 0" rpy="${PI/2} 0 0" />
      <geometry>
        <mesh filename="package://cpr_inspection_gazebo/meshes/urm04.STL" scale="0.001 0.001 0.001"/>
      </geometry>
      <material name="black" />
    </visual>
  </link>

    <link name="laser_scanner">
        <visual>
            <geometry>
                <box size="0.1 0.1 0.1"/>
            </geometry>
        </visual>

        <collision>
            <geometry>
                <box size="0.1 0.1 0.1"/>
            </geometry>
        </collision>

        <inertial>
            <mass value="1e-5"/>
            <inertia ixx="1e-6" ixy="0" ixz="0.0" iyy="1e-6" iyz="0.0" izz="1e-6"/>
        </inertial>
    </link>

    <joint name="laser_scanner_joint" type="fixed">
        <axis xyz="0.0 1 0.0"/>
        <parent link="base_link"/>
        <child link="laser_scanner"/>
        <origin xyz="0.0 0.0 0.08" rpy="0.0 0.0 0.0"/>
    </joint>

  <joint name="camera_joint" type="fixed">
    <axis xyz="0 1 0" />
    <origin xyz="0.3 0.0 0.05" rpy="0 0 0"/>
    <parent link="base_link"/>
    <child link="camera_link"/>
  </joint>

  <!-- Camera -->
  <link name="camera_link">
    <collision>
      <origin xyz="0 0 0" rpy="0 0 0"/>
      <geometry>
    <!-- <box size="${camera_size} ${camera_size} ${camera_size}"/> -->
    <box size="0.05 0.05 0.05"/>
      </geometry>
    </collision>

    <visual>
      <origin xyz="0 0 0" rpy="0 0 0"/>
      <geometry>
    <!-- <box size="${camera_size} ${camera_size} ${camera_size}"/> -->
        <box size="0.05 0.05 0.05"/>
      </geometry>
      <material name="white"/>
    </visual>

    <inertial>
      <mass value="1e-5" />
      <origin xyz="0 0 0" rpy="0 0 0"/>
      <inertia ixx="1e-6" ixy="0" ixz="0" iyy="1e-6" iyz="0" izz="1e-6" />
    </inertial>
  </link>

  <!-- camera -->
  <gazebo reference="camera_link">
    <sensor type="camera" name="camera1">
    <pose>0 0 0 0 0 0</pose>
    <visualize>true</visualize>
      <update_rate>30.0</update_rate>
      <camera name="head">
        <horizontal_fov>1.3962634</horizontal_fov>
        <image>
          <width>640</width>
          <height>480</height>
          <format>R8G8B8</format>
        </image>
        <clip>
          <near>0.02</near>
          <far>300</far>
        </clip>
        <noise>
          <type>gaussian</type>
          <!-- Noise is sampled independently per pixel on each frame.
               That pixel's noise value is added to each of its color
               channels, which at that point lie in the range [0,1]. -->
          <mean>0.0</mean>
          <stddev>0.007</stddev>
        </noise>
      </camera>
      <plugin name="camera_controller" filename="libgazebo_ros_camera.so">
        <alwaysOn>true</alwaysOn>
        <updateRate>0</updateRate>
        <cameraName>rrbot/camera1</cameraName>
        <imageTopicName>image_raw</imageTopicName>
        <cameraInfoTopicName>camera_info</cameraInfoTopicName>
        <frameName>camera_link</frameName>
        <hackBaseline>0.07</hackBaseline>
        <distortionK1>0.0</distortionK1>
        <distortionK2>0.0</distortionK2>
        <distortionK3>0.0</distortionK3>
        <distortionT1>0.0</distortionT1>
        <distortionT2>0.0</distortionT2>
      </plugin>
    </sensor>
  </gazebo>

    <gazebo reference="laser_scanner">
        <sensor type="ray" name="laser">
            <pose>0 0 0 0 0 0</pose>
            <visualize>true</visualize>
            <update_rate>40</update_rate>
            <ray>
                <scan>
                    <horizontal>
                        <samples>720</samples>
                        <resolution>1</resolution>
                        <min_angle>-1.578</min_angle>
                        <max_angle>1.578</max_angle>
                    </horizontal>
                </scan>
                <range>
                    <min>0.1</min>
                    <max>10</max>
                    <resolution>0.1</resolution>
                </range>
            </ray>
            <plugin name="Lidar" filename="libgazebo_ros_laser.so">
                <topicName>/scan</topicName>
                <frameName>laser_scanner</frameName>
            </plugin>
        </sensor>
    </gazebo>


  <!-- Include controller plugin for Gazebo -->
  <xacro:include filename="$(find cpr_inspection_gazebo)/urdf/nexus_4wd_mecanum.gazebo" />

  <!-- Include URM04 ultrasonic range finders -->
  <xacro:include filename="$(find cpr_inspection_gazebo)/urdf/urm04_sensor.xacro"/>
  <!-- front sensor -->
  <xacro:urm04_sensor frame_name="front_sensor" ros_topic="front_sensor" update_rate="10" min_range="0.04" max_range="2.5" horizontal_field_of_view="1.04" vertical_field_of_view="0.04" ray_count="2" />
  <!-- left sensor -->
  <xacro:urm04_sensor frame_name="left_sensor" ros_topic="left_sensor" update_rate="10" min_range="0.04" max_range="2.5" horizontal_field_of_view="1.04" vertical_field_of_view="0.04" ray_count="2" />
  <!-- right sensor -->
  <xacro:urm04_sensor frame_name="right_sensor" ros_topic="right_sensor" update_rate="10" min_range="0.04" max_range="2.5" horizontal_field_of_view="1.04" vertical_field_of_view="0.04" ray_count="2" />
  <!-- rear sensor -->
  <xacro:urm04_sensor frame_name="rear_sensor" ros_topic="rear_sensor" update_rate="10" min_range="0.04" max_range="2.5" horizontal_field_of_view="1.04" vertical_field_of_view="0.04" ray_count="2" />

</robot>
